Workbook
Name CategoryOptions: Settings!$F$2:INDEX(Settings!$F$2:$F$902,Settings!$I$3+1)
Name ZoneOptions: Settings!$D$2:INDEX(Settings!$D$2:$D$902,Settings!$I$2+1)

Sheet Dashboard
B2: Fresh Cart Grocery Performance Dashboard
B4: Start date | F4: End date | J4: Zone | P4: Category | X4: Delivery target minutes
B5: =MIN(Clean_Data[OrderDate]) -> 46266 | F5: =MAX(Clean_Data[OrderDate]) -> 46295 | J5: All | P5: All | X5: 30
B7: NET REVENUE | H7: TOTAL ORDERS | N7: UNIQUE CUSTOMERS | T7: AVG ORDER VALUE | Z7: AVG DELIVERY MIN
B8: =Analysis!B2 -> 310860.65 | H8: =Analysis!B3 -> 900 | N8: =Analysis!B5 -> 284 | T8: =Analysis!B6 -> 372.73459 | Z8: =Analysis!B7 -> 24.310552
B10: Orders include cancellations. Revenue, customers, AOV and delivery metrics use delivered orders.
B40: ORDER HEATMAP
B41: Day | D41: =Analysis!J55 -> Morning | F41: =Analysis!K55 -> Afternoon | H41: =Analysis!L55 -> Evening
B42: =Analysis!I56 -> Mon | D42: =Analysis!J56 -> 31 | F42: =Analysis!K56 -> 39 | H42: =Analysis!L56 -> 50
B43: =Analysis!I57 -> Tue | D43: =Analysis!J57 -> 49 | F43: =Analysis!K57 -> 39 | H43: =Analysis!L57 -> 62
B44: =Analysis!I58 -> Wed | D44: =Analysis!J58 -> 44 | F44: =Analysis!K58 -> 41 | H44: =Analysis!L58 -> 65
B45: =Analysis!I59 -> Thu | D45: =Analysis!J59 -> 41 | F45: =Analysis!K59 -> 38 | H45: =Analysis!L59 -> 41
B46: =Analysis!I60 -> Fri | D46: =Analysis!J60 -> 38 | F46: =Analysis!K60 -> 48 | H46: =Analysis!L60 -> 34
B47: =Analysis!I61 -> Sat | D47: =Analysis!J61 -> 29 | F47: =Analysis!K61 -> 41 | H47: =Analysis!L61 -> 50
B48: =Analysis!I62 -> Sun | D48: =Analysis!J62 -> 34 | F48: =Analysis!K62 -> 49 | H48: =Analysis!L62 -> 37
B50: Darker cells indicate more orders
B53: FULFILMENT | G53: ON TIME | M53: KEY INSIGHTS FOR THE SELECTED PERIOD
B54: =Analysis!B9 -> 0.92666667 | G54: =Analysis!B8 -> 0.75059952 | M54: =IF(Analysis!B2=0,"No delivered revenue in this selection.","Leading category: "&Analysis!L2&" ("&TEXT(Analysis!M2/Analysis!B2,"0.0%")&" of revenue)") -> Leading category: Beverages (26.0% of revenue)
M55: =IF(Analysis!B3=0,"No orders in this selection.","Peak time band: "&INDEX(Analysis!F21:F23,MATCH(MAX(Analysis!G21:G23),Analysis!G21:G23,0))) -> Peak time band: Evening
M56: =IF(Analysis!B4=0,"Delivery performance unavailable.","On-time delivery: "&TEXT(Analysis!B8,"0.0%")&" at "&TEXT(X5,"0")&" minutes") -> On-time delivery: 75.1% at 30 minutes
B57: FULFIL MIN | G57: AVG RATING | M57: =IF(Analysis!B3=0,"Cancellation rate unavailable.","Cancellation rate: "&TEXT(Analysis!B11,"0.0%")) -> Cancellation rate: 7.3%
B58: =Analysis!B10 -> 9.4784173 | G58: =Analysis!B12 -> 4.2505995

Sheet Analysis
A1: Metric | B1: Selected result | H1: Category | I1: Revenue | J1: Rank | L1: Category | M1: Revenue | O1: Product | P1: Revenue | Q1: Rank | T1: Product | U1: Revenue | W1: Zone | X1: Revenue
A2: Net revenue | B2: =SUMIFS(Clean_Data[NetRevenue],Clean_Data[Include],1) -> 310860.65 | H2: =IFERROR(INDEX(Clean!$G$2:$G$901,SMALL(Clean!$AC$2:$AC$901,ROWS($H$2:H2))),"") -> Bakery | I2: =SUMIFS(Clean_Data[NetRevenue],Clean_Data[Category],H2,Clean_Data[Include],1) -> 42028.75 | J2: =RANK(I2,$I$2:$I$7,0)+COUNTIFS($I$2:I2,I2)-1 -> 4 | L2: =INDEX($H$2:$H$7,MATCH(ROW()-1,$J$2:$J$7,0)) -> Beverages | M2: =INDEX($I$2:$I$7,MATCH(ROW()-1,$J$2:$J$7,0)) -> 80955 | O2: =IFERROR(INDEX(Clean!$H$2:$H$901,SMALL(Clean!$AD$2:$AD$901,ROWS($O$2:O2))),"") -> Croissants | P2: =SUMIFS(Clean_Data[NetRevenue],Clean_Data[Product],O2,Clean_Data[Include],1) -> 13342.75 | Q2: =RANK(P2,$P$2:$P$19,0)+COUNTIFS($P$2:P2,P2)-1 -> 10 | T2: =INDEX($O$2:$O$19,MATCH(ROW()-1,$Q$2:$Q$19,0)) -> Coffee | U2: =INDEX($P$2:$P$19,MATCH(ROW()-1,$Q$2:$Q$19,0)) -> 39468 | W2: =IFERROR(INDEX(Clean!$F$2:$F$901,SMALL(Clean!$AB$2:$AB$901,ROWS($W$2:W2))),"") -> Central | X2: =SUMIFS(Clean_Data[NetRevenue],Clean_Data[Zone],W2,Clean_Data[Include],1) -> 64779.95
A3: Total orders | B3: =SUM(Clean_Data[Include]) -> 900 | H3: =IFERROR(INDEX(Clean!$G$2:$G$901,SMALL(Clean!$AC$2:$AC$901,ROWS($H$2:H3))),"") -> Household | I3: =SUMIFS(Clean_Data[NetRevenue],Clean_Data[Category],H3,Clean_Data[Include],1) -> 68024.75 | J3: =RANK(I3,$I$2:$I$7,0)+COUNTIFS($I$2:I3,I3)-1 -> 2 | L3: =INDEX($H$2:$H$7,MATCH(ROW()-1,$J$2:$J$7,0)) -> Household | M3: =INDEX($I$2:$I$7,MATCH(ROW()-1,$J$2:$J$7,0)) -> 68024.75 | O3: =IFERROR(INDEX(Clean!$H$2:$H$901,SMALL(Clean!$AD$2:$AD$901,ROWS($O$2:O3))),"") -> Dish soap | P3: =SUMIFS(Clean_Data[NetRevenue],Clean_Data[Product],O3,Clean_Data[Include],1) -> 18918 | Q3: =RANK(P3,$P$2:$P$19,0)+COUNTIFS($P$2:P3,P3)-1 -> 8 | T3: =INDEX($O$2:$O$19,MATCH(ROW()-1,$Q$2:$Q$19,0)) -> Detergent | U3: =INDEX($P$2:$P$19,MATCH(ROW()-1,$Q$2:$Q$19,0)) -> 36684 | W3: =IFERROR(INDEX(Clean!$F$2:$F$901,SMALL(Clean!$AB$2:$AB$901,ROWS($W$2:W3))),"") -> West | X3: =SUMIFS(Clean_Data[NetRevenue],Clean_Data[Zone],W3,Clean_Data[Include],1) -> 67256
A4: Delivered orders | B4: =SUM(Clean_Data[DeliveredInclude]) -> 834 | H4: =IFERROR(INDEX(Clean!$G$2:$G$901,SMALL(Clean!$AC$2:$AC$901,ROWS($H$2:H4))),"") -> Beverages | I4: =SUMIFS(Clean_Data[NetRevenue],Clean_Data[Category],H4,Clean_Data[Include],1) -> 80955 | J4: =RANK(I4,$I$2:$I$7,0)+COUNTIFS($I$2:I4,I4)-1 -> 1 | L4: =INDEX($H$2:$H$7,MATCH(ROW()-1,$J$2:$J$7,0)) -> Snacks | M4: =INDEX($I$2:$I$7,MATCH(ROW()-1,$J$2:$J$7,0)) -> 43950 | O4: =IFERROR(INDEX(Clean!$H$2:$H$901,SMALL(Clean!$AD$2:$AD$901,ROWS($O$2:O4))),"") -> Detergent | P4: =SUMIFS(Clean_Data[NetRevenue],Clean_Data[Product],O4,Clean_Data[Include],1) -> 36684 | Q4: =RANK(P4,$P$2:$P$19,0)+COUNTIFS($P$2:P4,P4)-1 -> 2 | T4: =INDEX($O$2:$O$19,MATCH(ROW()-1,$Q$2:$Q$19,0)) -> Nuts | U4: =INDEX($P$2:$P$19,MATCH(ROW()-1,$Q$2:$Q$19,0)) -> 30591 | W4: =IFERROR(INDEX(Clean!$F$2:$F$901,SMALL(Clean!$AB$2:$AB$901,ROWS($W$2:W4))),"") -> North | X4: =SUMIFS(Clean_Data[NetRevenue],Clean_Data[Zone],W4,Clean_Data[Include],1) -> 62780.45
A5: Unique delivered customers | B5: =SUM(Customers!C2:C289) -> 284 | H5: =IFERROR(INDEX(Clean!$G$2:$G$901,SMALL(Clean!$AC$2:$AC$901,ROWS($H$2:H5))),"") -> Produce | I5: =SUMIFS(Clean_Data[NetRevenue],Clean_Data[Category],H5,Clean_Data[Include],1) -> 35687 | J5: =RANK(I5,$I$2:$I$7,0)+COUNTIFS($I$2:I5,I5)-1 -> 6 | L5: =INDEX($H$2:$H$7,MATCH(ROW()-1,$J$2:$J$7,0)) -> Bakery | M5: =INDEX($I$2:$I$7,MATCH(ROW()-1,$J$2:$J$7,0)) -> 42028.75 | O5: =IFERROR(INDEX(Clean!$H$2:$H$901,SMALL(Clean!$AD$2:$AD$901,ROWS($O$2:O5))),"") -> Juice | P5: =SUMIFS(Clean_Data[NetRevenue],Clean_Data[Product],O5,Clean_Data[Include],1) -> 13552.75 | Q5: =RANK(P5,$P$2:$P$19,0)+COUNTIFS($P$2:P5,P5)-1 -> 9 | T5: =INDEX($O$2:$O$19,MATCH(ROW()-1,$Q$2:$Q$19,0)) -> Tea | U5: =INDEX($P$2:$P$19,MATCH(ROW()-1,$Q$2:$Q$19,0)) -> 27934.25 | W5: =IFERROR(INDEX(Clean!$F$2:$F$901,SMALL(Clean!$AB$2:$AB$901,ROWS($W$2:W5))),"") -> South | X5: =SUMIFS(Clean_Data[NetRevenue],Clean_Data[Zone],W5,Clean_Data[Include],1) -> 55896.3
A6: Average delivered order value | B6: =IF(B4=0,"n.a.",B2/B4) -> 372.73459 | H6: =IFERROR(INDEX(Clean!$G$2:$G$901,SMALL(Clean!$AC$2:$AC$901,ROWS($H$2:H6))),"") -> Snacks | I6: =SUMIFS(Clean_Data[NetRevenue],Clean_Data[Category],H6,Clean_Data[Include],1) -> 43950 | J6: =RANK(I6,$I$2:$I$7,0)+COUNTIFS($I$2:I6,I6)-1 -> 3 | L6: =INDEX($H$2:$H$7,MATCH(ROW()-1,$J$2:$J$7,0)) -> Dairy | M6: =INDEX($I$2:$I$7,MATCH(ROW()-1,$J$2:$J$7,0)) -> 40215.15 | O6: =IFERROR(INDEX(Clean!$H$2:$H$901,SMALL(Clean!$AD$2:$AD$901,ROWS($O$2:O6))),"") -> Tea | P6: =SUMIFS(Clean_Data[NetRevenue],Clean_Data[Product],O6,Clean_Data[Include],1) -> 27934.25 | Q6: =RANK(P6,$P$2:$P$19,0)+COUNTIFS($P$2:P6,P6)-1 -> 4 | T6: =INDEX($O$2:$O$19,MATCH(ROW()-1,$Q$2:$Q$19,0)) -> Apples | U6: =INDEX($P$2:$P$19,MATCH(ROW()-1,$Q$2:$Q$19,0)) -> 24440 | W6: =IFERROR(INDEX(Clean!$F$2:$F$901,SMALL(Clean!$AB$2:$AB$901,ROWS($W$2:W6))),"") -> East | X6: =SUMIFS(Clean_Data[NetRevenue],Clean_Data[Zone],W6,Clean_Data[Include],1) -> 60147.95
A7: Average delivery minutes | B7: =IF(B4=0,"n.a.",SUMIFS(Clean_Data[DeliveryMinutes],Clean_Data[DeliveredInclude],1)/B4) -> 24.310552 | H7: =IFERROR(INDEX(Clean!$G$2:$G$901,SMALL(Clean!$AC$2:$AC$901,ROWS($H$2:H7))),"") -> Dairy | I7: =SUMIFS(Clean_Data[NetRevenue],Clean_Data[Category],H7,Clean_Data[Include],1) -> 40215.15 | J7: =RANK(I7,$I$2:$I$7,0)+COUNTIFS($I$2:I7,I7)-1 -> 5 | L7: =INDEX($H$2:$H$7,MATCH(ROW()-1,$J$2:$J$7,0)) -> Produce | M7: =INDEX($I$2:$I$7,MATCH(ROW()-1,$J$2:$J$7,0)) -> 35687 | O7: =IFERROR(INDEX(Clean!$H$2:$H$901,SMALL(Clean!$AD$2:$AD$901,ROWS($O$2:O7))),"") -> Bread | P7: =SUMIFS(Clean_Data[NetRevenue],Clean_Data[Product],O7,Clean_Data[Include],1) -> 7582.5 | Q7: =RANK(P7,$P$2:$P$19,0)+COUNTIFS($P$2:P7,P7)-1 -> 15
A8: On time rate | B8: =IF(B4=0,"n.a.",COUNTIFS(Clean_Data[DeliveredInclude],1,Clean_Data[OnTime],1)/B4) -> 0.75059952 | O8: =IFERROR(INDEX(Clean!$H$2:$H$901,SMALL(Clean!$AD$2:$AD$901,ROWS($O$2:O8))),"") -> Tomatoes | P8: =SUMIFS(Clean_Data[NetRevenue],Clean_Data[Product],O8,Clean_Data[Include],1) -> 5917.5 | Q8: =RANK(P8,$P$2:$P$19,0)+COUNTIFS($P$2:P8,P8)-1 -> 16
A9: Fulfilment rate | B9: =IF(B3=0,"n.a.",B4/B3) -> 0.92666667 | O9: =IFERROR(INDEX(Clean!$H$2:$H$901,SMALL(Clean!$AD$2:$AD$901,ROWS($O$2:O9))),"") -> Tissues | P9: =SUMIFS(Clean_Data[NetRevenue],Clean_Data[Product],O9,Clean_Data[Include],1) -> 12422.75 | Q9: =RANK(P9,$P$2:$P$19,0)+COUNTIFS($P$2:P9,P9)-1 -> 11
A10: Average fulfilment minutes | B10: =IF(B4=0,"n.a.",SUMIFS(Clean_Data[FulfilmentMinutes],Clean_Data[DeliveredInclude],1)/B4) -> 9.4784173 | O10: =IFERROR(INDEX(Clean!$H$2:$H$901,SMALL(Clean!$AD$2:$AD$901,ROWS($O$2:O10))),"") -> Chips | P10: =SUMIFS(Clean_Data[NetRevenue],Clean_Data[Product],O10,Clean_Data[Include],1) -> 4974 | Q10: =RANK(P10,$P$2:$P$19,0)+COUNTIFS($P$2:P10,P10)-1 -> 18
A11: Cancellation rate | B11: =IF(B3=0,"n.a.",(B3-B4)/B3) -> 0.073333333 | O11: =IFERROR(INDEX(Clean!$H$2:$H$901,SMALL(Clean!$AD$2:$AD$901,ROWS($O$2:O11))),"") -> Cookies | P11: =SUMIFS(Clean_Data[NetRevenue],Clean_Data[Product],O11,Clean_Data[Include],1) -> 21103.5 | Q11: =RANK(P11,$P$2:$P$19,0)+COUNTIFS($P$2:P11,P11)-1 -> 6
A12: Average rating | B12: =IF(B4=0,"n.a.",SUMIFS(Clean_Data[Rating],Clean_Data[DeliveredInclude],1)/B4) -> 4.2505995 | O12: =IFERROR(INDEX(Clean!$H$2:$H$901,SMALL(Clean!$AD$2:$AD$901,ROWS($O$2:O12))),"") -> Apples | P12: =SUMIFS(Clean_Data[NetRevenue],Clean_Data[Product],O12,Clean_Data[Include],1) -> 24440 | Q12: =RANK(P12,$P$2:$P$19,0)+COUNTIFS($P$2:P12,P12)-1 -> 5
O13: =IFERROR(INDEX(Clean!$H$2:$H$901,SMALL(Clean!$AD$2:$AD$901,ROWS($O$2:O13))),"") -> Nuts | P13: =SUMIFS(Clean_Data[NetRevenue],Clean_Data[Product],O13,Clean_Data[Include],1) -> 30591 | Q13: =RANK(P13,$P$2:$P$19,0)+COUNTIFS($P$2:P13,P13)-1 -> 3
O14: =IFERROR(INDEX(Clean!$H$2:$H$901,SMALL(Clean!$AD$2:$AD$901,ROWS($O$2:O14))),"") -> Cheese | P14: =SUMIFS(Clean_Data[NetRevenue],Clean_Data[Product],O14,Clean_Data[Include],1) -> 20839.75 | Q14: =RANK(P14,$P$2:$P$19,0)+COUNTIFS($P$2:P14,P14)-1 -> 7
O15: =IFERROR(INDEX(Clean!$H$2:$H$901,SMALL(Clean!$AD$2:$AD$901,ROWS($O$2:O15))),"") -> Milk | P15: =SUMIFS(Clean_Data[NetRevenue],Clean_Data[Product],O15,Clean_Data[Include],1) -> 9389.9 | Q15: =RANK(P15,$P$2:$P$19,0)+COUNTIFS($P$2:P15,P15)-1 -> 13
O16: =IFERROR(INDEX(Clean!$H$2:$H$901,SMALL(Clean!$AD$2:$AD$901,ROWS($O$2:O16))),"") -> Coffee | P16: =SUMIFS(Clean_Data[NetRevenue],Clean_Data[Product],O16,Clean_Data[Include],1) -> 39468 | Q16: =RANK(P16,$P$2:$P$19,0)+COUNTIFS($P$2:P16,P16)-1 -> 1
O17: =IFERROR(INDEX(Clean!$H$2:$H$901,SMALL(Clean!$AD$2:$AD$901,ROWS($O$2:O17))),"") -> Bananas | P17: =SUMIFS(Clean_Data[NetRevenue],Clean_Data[Product],O17,Clean_Data[Include],1) -> 5329.5 | Q17: =RANK(P17,$P$2:$P$19,0)+COUNTIFS($P$2:P17,P17)-1 -> 17
O18: =IFERROR(INDEX(Clean!$H$2:$H$901,SMALL(Clean!$AD$2:$AD$901,ROWS($O$2:O18))),"") -> Popcorn | P18: =SUMIFS(Clean_Data[NetRevenue],Clean_Data[Product],O18,Clean_Data[Include],1) -> 8385 | Q18: =RANK(P18,$P$2:$P$19,0)+COUNTIFS($P$2:P18,P18)-1 -> 14
O19: =IFERROR(INDEX(Clean!$H$2:$H$901,SMALL(Clean!$AD$2:$AD$901,ROWS($O$2:O19))),"") -> Yogurt | P19: =SUMIFS(Clean_Data[NetRevenue],Clean_Data[Product],O19,Clean_Data[Include],1) -> 9985.5 | Q19: =RANK(P19,$P$2:$P$19,0)+COUNTIFS($P$2:P19,P19)-1 -> 12
A20: Date | B20: Revenue | C20: Orders | D20: DateLabel | E20: TimeBandNo | F20: TimeBand | G20: Orders
A21: =IF(MIN(Clean_Data[OrderDate])+ROWS($A$21:A21)-1<=MAX(Clean_Data[OrderDate]),MIN(Clean_Data[OrderDate])+ROWS($A$21:A21)-1,"") -> 46266 | B21: =SUMIFS(Clean_Data[NetRevenue],Clean_Data[OrderDate],A21,Clean_Data[Include],1) -> 9906.25 | C21: =COUNTIFS(Clean_Data[OrderDate],A21,Clean_Data[Include],1) -> 30 | D21: =TEXT(A21,"dd-mmm") -> 01-Sep | E21: =IFERROR(SMALL(Clean!$AE$2:$AE$901,ROWS($E$21:E21)),"") -> 2 | F21: =INDEX(Clean_Data[TimeBand],MATCH(E21,Clean_Data[TimeBandNo],0)) -> Morning | G21: =COUNTIFS(Clean_Data[TimeBandNo],E21,Clean_Data[Include],1) -> 266
A22: =IF(MIN(Clean_Data[OrderDate])+ROWS($A$21:A22)-1<=MAX(Clean_Data[OrderDate]),MIN(Clean_Data[OrderDate])+ROWS($A$21:A22)-1,"") -> 46267 | B22: =SUMIFS(Clean_Data[NetRevenue],Clean_Data[OrderDate],A22,Clean_Data[Include],1) -> 8997.15 | C22: =COUNTIFS(Clean_Data[OrderDate],A22,Clean_Data[Include],1) -> 30 | D22: =TEXT(A22,"dd-mmm") -> 02-Sep | E22: =IFERROR(SMALL(Clean!$AE$2:$AE$901,ROWS($E$21:E22)),"") -> 3 | F22: =INDEX(Clean_Data[TimeBand],MATCH(E22,Clean_Data[TimeBandNo],0)) -> Afternoon | G22: =COUNTIFS(Clean_Data[TimeBandNo],E22,Clean_Data[Include],1) -> 295
A23: =IF(MIN(Clean_Data[OrderDate])+ROWS($A$21:A23)-1<=MAX(Clean_Data[OrderDate]),MIN(Clean_Data[OrderDate])+ROWS($A$21:A23)-1,"") -> 46268 | B23: =SUMIFS(Clean_Data[NetRevenue],Clean_Data[OrderDate],A23,Clean_Data[Include],1) -> 9217.75 | C23: =COUNTIFS(Clean_Data[OrderDate],A23,Clean_Data[Include],1) -> 30 | D23: =TEXT(A23,"dd-mmm") -> 03-Sep | E23: =IFERROR(SMALL(Clean!$AE$2:$AE$901,ROWS($E$21:E23)),"") -> 4 | F23: =INDEX(Clean_Data[TimeBand],MATCH(E23,Clean_Data[TimeBandNo],0)) -> Evening | G23: =COUNTIFS(Clean_Data[TimeBandNo],E23,Clean_Data[Include],1) -> 339
A24: =IF(MIN(Clean_Data[OrderDate])+ROWS($A$21:A24)-1<=MAX(Clean_Data[OrderDate]),MIN(Clean_Data[OrderDate])+ROWS($A$21:A24)-1,"") -> 46269 | B24: =SUMIFS(Clean_Data[NetRevenue],Clean_Data[OrderDate],A24,Clean_Data[Include],1) -> 13605.35 | C24: =COUNTIFS(Clean_Data[OrderDate],A24,Clean_Data[Include],1) -> 30 | D24: =TEXT(A24,"dd-mmm") -> 04-Sep
A25: =IF(MIN(Clean_Data[OrderDate])+ROWS($A$21:A25)-1<=MAX(Clean_Data[OrderDate]),MIN(Clean_Data[OrderDate])+ROWS($A$21:A25)-1,"") -> 46270 | B25: =SUMIFS(Clean_Data[NetRevenue],Clean_Data[OrderDate],A25,Clean_Data[Include],1) -> 11834.95 | C25: =COUNTIFS(Clean_Data[OrderDate],A25,Clean_Data[Include],1) -> 30 | D25: =TEXT(A25,"dd-mmm") -> 05-Sep
A26: =IF(MIN(Clean_Data[OrderDate])+ROWS($A$21:A26)-1<=MAX(Clean_Data[OrderDate]),MIN(Clean_Data[OrderDate])+ROWS($A$21:A26)-1,"") -> 46271 | B26: =SUMIFS(Clean_Data[NetRevenue],Clean_Data[OrderDate],A26,Clean_Data[Include],1) -> 9340.2 | C26: =COUNTIFS(Clean_Data[OrderDate],A26,Clean_Data[Include],1) -> 30 | D26: =TEXT(A26,"dd-mmm") -> 06-Sep
A27: =IF(MIN(Clean_Data[OrderDate])+ROWS($A$21:A27)-1<=MAX(Clean_Data[OrderDate]),MIN(Clean_Data[OrderDate])+ROWS($A$21:A27)-1,"") -> 46272 | B27: =SUMIFS(Clean_Data[NetRevenue],Clean_Data[OrderDate],A27,Clean_Data[Include],1) -> 8267.5 | C27: =COUNTIFS(Clean_Data[OrderDate],A27,Clean_Data[Include],1) -> 30 | D27: =TEXT(A27,"dd-mmm") -> 07-Sep
A28: =IF(MIN(Clean_Data[OrderDate])+ROWS($A$21:A28)-1<=MAX(Clean_Data[OrderDate]),MIN(Clean_Data[OrderDate])+ROWS($A$21:A28)-1,"") -> 46273 | B28: =SUMIFS(Clean_Data[NetRevenue],Clean_Data[OrderDate],A28,Clean_Data[Include],1) -> 12269.25 | C28: =COUNTIFS(Clean_Data[OrderDate],A28,Clean_Data[Include],1) -> 30 | D28: =TEXT(A28,"dd-mmm") -> 08-Sep
A29: =IF(MIN(Clean_Data[OrderDate])+ROWS($A$21:A29)-1<=MAX(Clean_Data[OrderDate]),MIN(Clean_Data[OrderDate])+ROWS($A$21:A29)-1,"") -> 46274 | B29: =SUMIFS(Clean_Data[NetRevenue],Clean_Data[OrderDate],A29,Clean_Data[Include],1) -> 9703.75 | C29: =COUNTIFS(Clean_Data[OrderDate],A29,Clean_Data[Include],1) -> 30 | D29: =TEXT(A29,"dd-mmm") -> 09-Sep
A30: =IF(MIN(Clean_Data[OrderDate])+ROWS($A$21:A30)-1<=MAX(Clean_Data[OrderDate]),MIN(Clean_Data[OrderDate])+ROWS($A$21:A30)-1,"") -> 46275 | B30: =SUMIFS(Clean_Data[NetRevenue],Clean_Data[OrderDate],A30,Clean_Data[Include],1) -> 10117.25 | C30: =COUNTIFS(Clean_Data[OrderDate],A30,Clean_Data[Include],1) -> 30 | D30: =TEXT(A30,"dd-mmm") -> 10-Sep
A31: =IF(MIN(Clean_Data[OrderDate])+ROWS($A$21:A31)-1<=MAX(Clean_Data[OrderDate]),MIN(Clean_Data[OrderDate])+ROWS($A$21:A31)-1,"") -> 46276 | B31: =SUMIFS(Clean_Data[NetRevenue],Clean_Data[OrderDate],A31,Clean_Data[Include],1) -> 12683 | C31: =COUNTIFS(Clean_Data[OrderDate],A31,Clean_Data[Include],1) -> 30 | D31: =TEXT(A31,"dd-mmm") -> 11-Sep
A32: =IF(MIN(Clean_Data[OrderDate])+ROWS($A$21:A32)-1<=MAX(Clean_Data[OrderDate]),MIN(Clean_Data[OrderDate])+ROWS($A$21:A32)-1,"") -> 46277 | B32: =SUMIFS(Clean_Data[NetRevenue],Clean_Data[OrderDate],A32,Clean_Data[Include],1) -> 8433 | C32: =COUNTIFS(Clean_Data[OrderDate],A32,Clean_Data[Include],1) -> 30 | D32: =TEXT(A32,"dd-mmm") -> 12-Sep
A33: =IF(MIN(Clean_Data[OrderDate])+ROWS($A$21:A33)-1<=MAX(Clean_Data[OrderDate]),MIN(Clean_Data[OrderDate])+ROWS($A$21:A33)-1,"") -> 46278 | B33: =SUMIFS(Clean_Data[NetRevenue],Clean_Data[OrderDate],A33,Clean_Data[Include],1) -> 9943.7 | C33: =COUNTIFS(Clean_Data[OrderDate],A33,Clean_Data[Include],1) -> 30 | D33: =TEXT(A33,"dd-mmm") -> 13-Sep
A34: =IF(MIN(Clean_Data[OrderDate])+ROWS($A$21:A34)-1<=MAX(Clean_Data[OrderDate]),MIN(Clean_Data[OrderDate])+ROWS($A$21:A34)-1,"") -> 46279 | B34: =SUMIFS(Clean_Data[NetRevenue],Clean_Data[OrderDate],A34,Clean_Data[Include],1) -> 9549.5 | C34: =COUNTIFS(Clean_Data[OrderDate],A34,Clean_Data[Include],1) -> 30 | D34: =TEXT(A34,"dd-mmm") -> 14-Sep
A35: =IF(MIN(Clean_Data[OrderDate])+ROWS($A$21:A35)-1<=MAX(Clean_Data[OrderDate]),MIN(Clean_Data[OrderDate])+ROWS($A$21:A35)-1,"") -> 46280 | B35: =SUMIFS(Clean_Data[NetRevenue],Clean_Data[OrderDate],A35,Clean_Data[Include],1) -> 9134 | C35: =COUNTIFS(Clean_Data[OrderDate],A35,Clean_Data[Include],1) -> 30 | D35: =TEXT(A35,"dd-mmm") -> 15-Sep
... A50: =IF(MIN(Clean_Data[OrderDate])+ROWS($A$21:A50)-1<=MAX(Clean_Data[OrderDate]),MIN(Clean_Data[OrderDate])+ROWS($A$21:A50)-1,"") -> 46295 | B50: =SUMIFS(Clean_Data[NetRevenue],Clean_Data[OrderDate],A50,Clean_Data[Include],1) -> 10806 | C50: =COUNTIFS(Clean_Data[OrderDate],A50,Clean_Data[Include],1) -> 30 | D50: =TEXT(A50,"dd-mmm") -> 30-Sep
A55: Customer cohort | B55: Delivered orders | E55: Delivery | F55: Delivered orders | H55: WeekdayNo | I55: Day | J55: =F21 -> Morning | K55: =F22 -> Afternoon | L55: =F23 -> Evening
A56: =IFERROR(INDEX(Clean!$E$2:$E$901,SMALL(Clean!$AG$2:$AG$901,ROWS($A$56:A56))),"") -> Returning | B56: =COUNTIFS(Clean_Data[CustomerType],A56,Clean_Data[DeliveredInclude],1) -> 591 | E56: On time | F56: =COUNTIFS(Clean_Data[DeliveredInclude],1,Clean_Data[OnTime],1) -> 626 | H56: =IFERROR(SMALL(Clean!$AF$2:$AF$901,ROWS($H$56:H56)),"") -> 1 | I56: =INDEX(Clean_Data[Weekday],MATCH(H56,Clean_Data[WeekdayNo],0)) -> Mon | J56: =COUNTIFS(Clean_Data[WeekdayNo],$H56,Clean_Data[TimeBand],J$55,Clean_Data[Include],1) -> 31 | K56: =COUNTIFS(Clean_Data[WeekdayNo],$H56,Clean_Data[TimeBand],K$55,Clean_Data[Include],1) -> 39 | L56: =COUNTIFS(Clean_Data[WeekdayNo],$H56,Clean_Data[TimeBand],L$55,Clean_Data[Include],1) -> 50
A57: =IFERROR(INDEX(Clean!$E$2:$E$901,SMALL(Clean!$AG$2:$AG$901,ROWS($A$56:A57))),"") -> New | B57: =COUNTIFS(Clean_Data[CustomerType],A57,Clean_Data[DeliveredInclude],1) -> 243 | E57: Late | F57: =COUNTIFS(Clean_Data[DeliveredInclude],1,Clean_Data[OnTime],0) -> 208 | H57: =IFERROR(SMALL(Clean!$AF$2:$AF$901,ROWS($H$56:H57)),"") -> 2 | I57: =INDEX(Clean_Data[Weekday],MATCH(H57,Clean_Data[WeekdayNo],0)) -> Tue | J57: =COUNTIFS(Clean_Data[WeekdayNo],$H57,Clean_Data[TimeBand],J$55,Clean_Data[Include],1) -> 49 | K57: =COUNTIFS(Clean_Data[WeekdayNo],$H57,Clean_Data[TimeBand],K$55,Clean_Data[Include],1) -> 39 | L57: =COUNTIFS(Clean_Data[WeekdayNo],$H57,Clean_Data[TimeBand],L$55,Clean_Data[Include],1) -> 62
H58: =IFERROR(SMALL(Clean!$AF$2:$AF$901,ROWS($H$56:H58)),"") -> 3 | I58: =INDEX(Clean_Data[Weekday],MATCH(H58,Clean_Data[WeekdayNo],0)) -> Wed | J58: =COUNTIFS(Clean_Data[WeekdayNo],$H58,Clean_Data[TimeBand],J$55,Clean_Data[Include],1) -> 44 | K58: =COUNTIFS(Clean_Data[WeekdayNo],$H58,Clean_Data[TimeBand],K$55,Clean_Data[Include],1) -> 41 | L58: =COUNTIFS(Clean_Data[WeekdayNo],$H58,Clean_Data[TimeBand],L$55,Clean_Data[Include],1) -> 65
...

Sheet Customers
A1: CustomerID | B1: Selected delivered orders | C1: Active | E1: Observed CustomerIDs
A2: =IFERROR(INDEX(Clean!$D$2:$D$901,SMALL(Clean!$AA$2:$AA$901,ROWS($A$2:A2))),"") -> C189 | B2: =COUNTIFS(Clean_Data[CustomerID],A2,Clean_Data[DeliveredInclude],1) -> 4 | C2: =IF(B2>0,1,0) -> 1 | E2: =COUNTIF(Clean!$AA$2:$AA$901,"<="&ROWS(Clean_Data[OrderID])) -> 288
A3: =IFERROR(INDEX(Clean!$D$2:$D$901,SMALL(Clean!$AA$2:$AA$901,ROWS($A$2:A3))),"") -> C255 | B3: =COUNTIFS(Clean_Data[CustomerID],A3,Clean_Data[DeliveredInclude],1) -> 4 | C3: =IF(B3>0,1,0) -> 1
A4: =IFERROR(INDEX(Clean!$D$2:$D$901,SMALL(Clean!$AA$2:$AA$901,ROWS($A$2:A4))),"") -> C095 | B4: =COUNTIFS(Clean_Data[CustomerID],A4,Clean_Data[DeliveredInclude],1) -> 3 | C4: =IF(B4>0,1,0) -> 1
A5: =IFERROR(INDEX(Clean!$D$2:$D$901,SMALL(Clean!$AA$2:$AA$901,ROWS($A$2:A5))),"") -> C290 | B5: =COUNTIFS(Clean_Data[CustomerID],A5,Clean_Data[DeliveredInclude],1) -> 2 | C5: =IF(B5>0,1,0) -> 1
A6: =IFERROR(INDEX(Clean!$D$2:$D$901,SMALL(Clean!$AA$2:$AA$901,ROWS($A$2:A6))),"") -> C225 | B6: =COUNTIFS(Clean_Data[CustomerID],A6,Clean_Data[DeliveredInclude],1) -> 2 | C6: =IF(B6>0,1,0) -> 1
A7: =IFERROR(INDEX(Clean!$D$2:$D$901,SMALL(Clean!$AA$2:$AA$901,ROWS($A$2:A7))),"") -> C117 | B7: =COUNTIFS(Clean_Data[CustomerID],A7,Clean_Data[DeliveredInclude],1) -> 3 | C7: =IF(B7>0,1,0) -> 1
A8: =IFERROR(INDEX(Clean!$D$2:$D$901,SMALL(Clean!$AA$2:$AA$901,ROWS($A$2:A8))),"") -> C077 | B8: =COUNTIFS(Clean_Data[CustomerID],A8,Clean_Data[DeliveredInclude],1) -> 4 | C8: =IF(B8>0,1,0) -> 1
A9: =IFERROR(INDEX(Clean!$D$2:$D$901,SMALL(Clean!$AA$2:$AA$901,ROWS($A$2:A9))),"") -> C124 | B9: =COUNTIFS(Clean_Data[CustomerID],A9,Clean_Data[DeliveredInclude],1) -> 6 | C9: =IF(B9>0,1,0) -> 1
A10: =IFERROR(INDEX(Clean!$D$2:$D$901,SMALL(Clean!$AA$2:$AA$901,ROWS($A$2:A10))),"") -> C145 | B10: =COUNTIFS(Clean_Data[CustomerID],A10,Clean_Data[DeliveredInclude],1) -> 4 | C10: =IF(B10>0,1,0) -> 1
A11: =IFERROR(INDEX(Clean!$D$2:$D$901,SMALL(Clean!$AA$2:$AA$901,ROWS($A$2:A11))),"") -> C249 | B11: =COUNTIFS(Clean_Data[CustomerID],A11,Clean_Data[DeliveredInclude],1) -> 1 | C11: =IF(B11>0,1,0) -> 1
A12: =IFERROR(INDEX(Clean!$D$2:$D$901,SMALL(Clean!$AA$2:$AA$901,ROWS($A$2:A12))),"") -> C233 | B12: =COUNTIFS(Clean_Data[CustomerID],A12,Clean_Data[DeliveredInclude],1) -> 1 | C12: =IF(B12>0,1,0) -> 1
A13: =IFERROR(INDEX(Clean!$D$2:$D$901,SMALL(Clean!$AA$2:$AA$901,ROWS($A$2:A13))),"") -> C134 | B13: =COUNTIFS(Clean_Data[CustomerID],A13,Clean_Data[DeliveredInclude],1) -> 4 | C13: =IF(B13>0,1,0) -> 1
A14: =IFERROR(INDEX(Clean!$D$2:$D$901,SMALL(Clean!$AA$2:$AA$901,ROWS($A$2:A14))),"") -> C257 | B14: =COUNTIFS(Clean_Data[CustomerID],A14,Clean_Data[DeliveredInclude],1) -> 1 | C14: =IF(B14>0,1,0) -> 1
... A289: =IFERROR(INDEX(Clean!$D$2:$D$901,SMALL(Clean!$AA$2:$AA$901,ROWS($A$2:A289))),"") -> C254 | B289: =COUNTIFS(Clean_Data[CustomerID],A289,Clean_Data[DeliveredInclude],1) -> 0 | C289: =IF(B289>0,1,0) -> 0

Sheet Settings
D1: Zone choices | F1: Category choices | H1: List / daily span | I1: Count from data
A2: Start date | B2: =Dashboard!B5 -> 46266 | D2: All | F2: All | H2: Zones | I2: =COUNTIF(Clean!$AB$2:$AB$901,"<="&ROWS(Clean_Data[OrderID])) -> 5
A3: End date | B3: =Dashboard!F5 -> 46295 | D3: =IFERROR(INDEX(Clean!$F$2:$F$901,SMALL(Clean!$AB$2:$AB$901,ROWS($D$3:D3))),"") -> Central | F3: =IFERROR(INDEX(Clean!$G$2:$G$901,SMALL(Clean!$AC$2:$AC$901,ROWS($F$3:F3))),"") -> Bakery | H3: Categories | I3: =COUNTIF(Clean!$AC$2:$AC$901,"<="&ROWS(Clean_Data[OrderID])) -> 6
A4: Zone | B4: =Dashboard!J5 -> All | D4: =IFERROR(INDEX(Clean!$F$2:$F$901,SMALL(Clean!$AB$2:$AB$901,ROWS($D$3:D4))),"") -> West | F4: =IFERROR(INDEX(Clean!$G$2:$G$901,SMALL(Clean!$AC$2:$AC$901,ROWS($F$3:F4))),"") -> Household | H4: Products | I4: =COUNTIF(Clean!$AD$2:$AD$901,"<="&ROWS(Clean_Data[OrderID])) -> 18
A5: Category | B5: =Dashboard!P5 -> All | D5: =IFERROR(INDEX(Clean!$F$2:$F$901,SMALL(Clean!$AB$2:$AB$901,ROWS($D$3:D5))),"") -> North | F5: =IFERROR(INDEX(Clean!$G$2:$G$901,SMALL(Clean!$AC$2:$AC$901,ROWS($F$3:F5))),"") -> Beverages | H5: Observed customers | I5: =COUNTIF(Clean!$AA$2:$AA$901,"<="&ROWS(Clean_Data[OrderID])) -> 288
A6: Delivery target minutes | B6: =Dashboard!X5 -> 30 | D6: =IFERROR(INDEX(Clean!$F$2:$F$901,SMALL(Clean!$AB$2:$AB$901,ROWS($D$3:D6))),"") -> South | F6: =IFERROR(INDEX(Clean!$G$2:$G$901,SMALL(Clean!$AC$2:$AC$901,ROWS($F$3:F6))),"") -> Produce | H6: Time bands | I6: =COUNTIF(Clean!$AE$2:$AE$901,"<="&ROWS(Clean_Data[OrderID])) -> 3
D7: =IFERROR(INDEX(Clean!$F$2:$F$901,SMALL(Clean!$AB$2:$AB$901,ROWS($D$3:D7))),"") -> East | F7: =IFERROR(INDEX(Clean!$G$2:$G$901,SMALL(Clean!$AC$2:$AC$901,ROWS($F$3:F7))),"") -> Snacks | H7: Weekdays | I7: =COUNTIF(Clean!$AF$2:$AF$901,"<="&ROWS(Clean_Data[OrderID])) -> 7
A8: Teaching assumption: 30 minute delivery target | F8: =IFERROR(INDEX(Clean!$G$2:$G$901,SMALL(Clean!$AC$2:$AC$901,ROWS($F$3:F8))),"") -> Dairy | H8: Calendar days | I8: =MAX(Clean_Data[OrderDate])-MIN(Clean_Data[OrderDate])+1 -> 30
H10: Excel 2016: fill helpers and summaries down when adding source rows.

Sheet Clean
A1: OrderID | B1: OrderDate | C1: OrderHour | D1: CustomerID | E1: CustomerType | F1: Zone | G1: Category | H1: Product | I1: Quantity | J1: UnitPrice | K1: DiscountPct | L1: Status | M1: DeliveryMinutes | N1: FulfilmentMinutes | O1: Rating | P1: GrossSales | Q1: DiscountAmount | R1: NetRevenue | S1: TimeBand | T1: Weekday | U1: WeekdayNo | V1: TimeBandNo | W1: DeliveredFlag | X1: OnTime | Y1: Include | Z1: DeliveredInclude | AA1: CustomerFirstRow | AB1: ZoneFirstRow | AC1: CategoryFirstRow | AD1: ProductFirstRow | AE1: TimeFirstCode | AF1: WeekdayFirstCode | AG1: CohortFirstRow
A2: G0001 | B2: 46266 | C2: 13 | D2: C189 | E2: Returning | F2: Central | G2: Bakery | H2: Croissants | I2: 3 | J2: 95 | K2: 0 | L2: Delivered | M2: 24 | N2: 13 | O2: 5 | P2: =Clean_Data[[#This Row],[Quantity]]*Clean_Data[[#This Row],[UnitPrice]] -> 285 | Q2: =ROUND(Clean_Data[[#This Row],[GrossSales]]*Clean_Data[[#This Row],[DiscountPct]],2) -> 0 | R2: =IF(Clean_Data[[#This Row],[Status]]="Delivered",ROUND(Clean_Data[[#This Row],[GrossSales]]-Clean_Data[[#This Row],[DiscountAmount]],2),0) -> 285 | S2: =IF(Clean_Data[[#This Row],[OrderHour]]<6,"Night",IF(Clean_Data[[#This Row],[OrderHour]]<12,"Morning",IF(Clean_Data[[#This Row],[OrderHour]]<18,"Afternoon","Evening"))) -> Afternoon | T2: =TEXT(Clean_Data[[#This Row],[OrderDate]],"[$-409]ddd") -> Tue | U2: =WEEKDAY(Clean_Data[[#This Row],[OrderDate]],2) -> 2 | V2: =INT(Clean_Data[[#This Row],[OrderHour]]/6)+1 -> 3 | W2: =IF(Clean_Data[[#This Row],[Status]]="Delivered",1,0) -> 1 | X2: =IF(Clean_Data[[#This Row],[Status]]="Delivered",IF(Clean_Data[[#This Row],[DeliveryMinutes]]<=Dashboard!$X$5,1,0),0) -> 1 | Y2: =IF(AND(Clean_Data[[#This Row],[OrderDate]]>=Dashboard!$B$5,Clean_Data[[#This Row],[OrderDate]]<=Dashboard!$F$5,OR(Dashboard!$J$5="All",Clean_Data[[#This Row],[Zone]]=Dashboard!$J$5),OR(Dashboard!$P$5="All",Clean_Data[[#This Row],[Category]]=Dashboard!$P$5)),1,0) -> 1 | Z2: =IF(AND(Clean_Data[[#This Row],[Include]]=1,Clean_Data[[#This Row],[DeliveredFlag]]=1),1,0) -> 1 | AA2: =IF(COUNTIF($D$2:D2,D2)=1,ROW()-1,ROWS(Clean_Data[OrderID])+1) -> 1 | AB2: =IF(COUNTIF($F$2:F2,F2)=1,ROW()-1,ROWS(Clean_Data[OrderID])+1) -> 1 | AC2: =IF(COUNTIF($G$2:G2,G2)=1,ROW()-1,ROWS(Clean_Data[OrderID])+1) -> 1 | AD2: =IF(COUNTIF($H$2:H2,H2)=1,ROW()-1,ROWS(Clean_Data[OrderID])+1) -> 1 | AE2: =IF(COUNTIF($V$2:V2,V2)=1,V2,ROWS(Clean_Data[OrderID])+1) -> 3 | AF2: =IF(COUNTIF($U$2:U2,U2)=1,U2,ROWS(Clean_Data[OrderID])+1) -> 2 | AG2: =IF(COUNTIF($E$2:E2,E2)=1,ROW()-1,ROWS(Clean_Data[OrderID])+1) -> 1
A3: G0002 | B3: 46266 | C3: 16 | D3: C255 | E3: Returning | F3: West | G3: Household | H3: Dish soap | I3: 5 | J3: 120 | K3: 0.1 | L3: Cancelled | P3: =Clean_Data[[#This Row],[Quantity]]*Clean_Data[[#This Row],[UnitPrice]] -> 600 | Q3: =ROUND(Clean_Data[[#This Row],[GrossSales]]*Clean_Data[[#This Row],[DiscountPct]],2) -> 60 | R3: =IF(Clean_Data[[#This Row],[Status]]="Delivered",ROUND(Clean_Data[[#This Row],[GrossSales]]-Clean_Data[[#This Row],[DiscountAmount]],2),0) -> 0 | S3: =IF(Clean_Data[[#This Row],[OrderHour]]<6,"Night",IF(Clean_Data[[#This Row],[OrderHour]]<12,"Morning",IF(Clean_Data[[#This Row],[OrderHour]]<18,"Afternoon","Evening"))) -> Afternoon | T3: =TEXT(Clean_Data[[#This Row],[OrderDate]],"[$-409]ddd") -> Tue | U3: =WEEKDAY(Clean_Data[[#This Row],[OrderDate]],2) -> 2 | V3: =INT(Clean_Data[[#This Row],[OrderHour]]/6)+1 -> 3 | W3: =IF(Clean_Data[[#This Row],[Status]]="Delivered",1,0) -> 0 | X3: =IF(Clean_Data[[#This Row],[Status]]="Delivered",IF(Clean_Data[[#This Row],[DeliveryMinutes]]<=Dashboard!$X$5,1,0),0) -> 0 | Y3: =IF(AND(Clean_Data[[#This Row],[OrderDate]]>=Dashboard!$B$5,Clean_Data[[#This Row],[OrderDate]]<=Dashboard!$F$5,OR(Dashboard!$J$5="All",Clean_Data[[#This Row],[Zone]]=Dashboard!$J$5),OR(Dashboard!$P$5="All",Clean_Data[[#This Row],[Category]]=Dashboard!$P$5)),1,0) -> 1 | Z3: =IF(AND(Clean_Data[[#This Row],[Include]]=1,Clean_Data[[#This Row],[DeliveredFlag]]=1),1,0) -> 0 | AA3: =IF(COUNTIF($D$2:D3,D3)=1,ROW()-1,ROWS(Clean_Data[OrderID])+1) -> 2 | AB3: =IF(COUNTIF($F$2:F3,F3)=1,ROW()-1,ROWS(Clean_Data[OrderID])+1) -> 2 | AC3: =IF(COUNTIF($G$2:G3,G3)=1,ROW()-1,ROWS(Clean_Data[OrderID])+1) -> 2 | AD3: =IF(COUNTIF($H$2:H3,H3)=1,ROW()-1,ROWS(Clean_Data[OrderID])+1) -> 2 | AE3: =IF(COUNTIF($V$2:V3,V3)=1,V3,ROWS(Clean_Data[OrderID])+1) -> 901 | AF3: =IF(COUNTIF($U$2:U3,U3)=1,U3,ROWS(Clean_Data[OrderID])+1) -> 901 | AG3: =IF(COUNTIF($E$2:E3,E3)=1,ROW()-1,ROWS(Clean_Data[OrderID])+1) -> 901
A4: G0003 | B4: 46266 | C4: 18 | D4: C095 | E4: Returning | F4: Central | G4: Household | H4: Detergent | I4: 4 | J4: 240 | K4: 0 | L4: Delivered | M4: 30 | N4: 9 | O4: 5 | P4: =Clean_Data[[#This Row],[Quantity]]*Clean_Data[[#This Row],[UnitPrice]] -> 960 | Q4: =ROUND(Clean_Data[[#This Row],[GrossSales]]*Clean_Data[[#This Row],[DiscountPct]],2) -> 0 | R4: =IF(Clean_Data[[#This Row],[Status]]="Delivered",ROUND(Clean_Data[[#This Row],[GrossSales]]-Clean_Data[[#This Row],[DiscountAmount]],2),0) -> 960 | S4: =IF(Clean_Data[[#This Row],[OrderHour]]<6,"Night",IF(Clean_Data[[#This Row],[OrderHour]]<12,"Morning",IF(Clean_Data[[#This Row],[OrderHour]]<18,"Afternoon","Evening"))) -> Evening | T4: =TEXT(Clean_Data[[#This Row],[OrderDate]],"[$-409]ddd") -> Tue | U4: =WEEKDAY(Clean_Data[[#This Row],[OrderDate]],2) -> 2 | V4: =INT(Clean_Data[[#This Row],[OrderHour]]/6)+1 -> 4 | W4: =IF(Clean_Data[[#This Row],[Status]]="Delivered",1,0) -> 1 | X4: =IF(Clean_Data[[#This Row],[Status]]="Delivered",IF(Clean_Data[[#This Row],[DeliveryMinutes]]<=Dashboard!$X$5,1,0),0) -> 1 | Y4: =IF(AND(Clean_Data[[#This Row],[OrderDate]]>=Dashboard!$B$5,Clean_Data[[#This Row],[OrderDate]]<=Dashboard!$F$5,OR(Dashboard!$J$5="All",Clean_Data[[#This Row],[Zone]]=Dashboard!$J$5),OR(Dashboard!$P$5="All",Clean_Data[[#This Row],[Category]]=Dashboard!$P$5)),1,0) -> 1 | Z4: =IF(AND(Clean_Data[[#This Row],[Include]]=1,Clean_Data[[#This Row],[DeliveredFlag]]=1),1,0) -> 1 | AA4: =IF(COUNTIF($D$2:D4,D4)=1,ROW()-1,ROWS(Clean_Data[OrderID])+1) -> 3 | AB4: =IF(COUNTIF($F$2:F4,F4)=1,ROW()-1,ROWS(Clean_Data[OrderID])+1) -> 901 | AC4: =IF(COUNTIF($G$2:G4,G4)=1,ROW()-1,ROWS(Clean_Data[OrderID])+1) -> 901 | AD4: =IF(COUNTIF($H$2:H4,H4)=1,ROW()-1,ROWS(Clean_Data[OrderID])+1) -> 3 | AE4: =IF(COUNTIF($V$2:V4,V4)=1,V4,ROWS(Clean_Data[OrderID])+1) -> 4 | AF4: =IF(COUNTIF($U$2:U4,U4)=1,U4,ROWS(Clean_Data[OrderID])+1) -> 901 | AG4: =IF(COUNTIF($E$2:E4,E4)=1,ROW()-1,ROWS(Clean_Data[OrderID])+1) -> 901
A5: G0004 | B5: 46266 | C5: 17 | D5: C290 | E5: Returning | F5: West | G5: Household | H5: Detergent | I5: 2 | J5: 240 | K5: 0 | L5: Cancelled | P5: =Clean_Data[[#This Row],[Quantity]]*Clean_Data[[#This Row],[UnitPrice]] -> 480 | Q5: =ROUND(Clean_Data[[#This Row],[GrossSales]]*Clean_Data[[#This Row],[DiscountPct]],2) -> 0 | R5: =IF(Clean_Data[[#This Row],[Status]]="Delivered",ROUND(Clean_Data[[#This Row],[GrossSales]]-Clean_Data[[#This Row],[DiscountAmount]],2),0) -> 0 | S5: =IF(Clean_Data[[#This Row],[OrderHour]]<6,"Night",IF(Clean_Data[[#This Row],[OrderHour]]<12,"Morning",IF(Clean_Data[[#This Row],[OrderHour]]<18,"Afternoon","Evening"))) -> Afternoon | T5: =TEXT(Clean_Data[[#This Row],[OrderDate]],"[$-409]ddd") -> Tue | U5: =WEEKDAY(Clean_Data[[#This Row],[OrderDate]],2) -> 2 | V5: =INT(Clean_Data[[#This Row],[OrderHour]]/6)+1 -> 3 | W5: =IF(Clean_Data[[#This Row],[Status]]="Delivered",1,0) -> 0 | X5: =IF(Clean_Data[[#This Row],[Status]]="Delivered",IF(Clean_Data[[#This Row],[DeliveryMinutes]]<=Dashboard!$X$5,1,0),0) -> 0 | Y5: =IF(AND(Clean_Data[[#This Row],[OrderDate]]>=Dashboard!$B$5,Clean_Data[[#This Row],[OrderDate]]<=Dashboard!$F$5,OR(Dashboard!$J$5="All",Clean_Data[[#This Row],[Zone]]=Dashboard!$J$5),OR(Dashboard!$P$5="All",Clean_Data[[#This Row],[Category]]=Dashboard!$P$5)),1,0) -> 1 | Z5: =IF(AND(Clean_Data[[#This Row],[Include]]=1,Clean_Data[[#This Row],[DeliveredFlag]]=1),1,0) -> 0 | AA5: =IF(COUNTIF($D$2:D5,D5)=1,ROW()-1,ROWS(Clean_Data[OrderID])+1) -> 4 | AB5: =IF(COUNTIF($F$2:F5,F5)=1,ROW()-1,ROWS(Clean_Data[OrderID])+1) -> 901 | AC5: =IF(COUNTIF($G$2:G5,G5)=1,ROW()-1,ROWS(Clean_Data[OrderID])+1) -> 901 | AD5: =IF(COUNTIF($H$2:H5,H5)=1,ROW()-1,ROWS(Clean_Data[OrderID])+1) -> 901 | AE5: =IF(COUNTIF($V$2:V5,V5)=1,V5,ROWS(Clean_Data[OrderID])+1) -> 901 | AF5: =IF(COUNTIF($U$2:U5,U5)=1,U5,ROWS(Clean_Data[OrderID])+1) -> 901 | AG5: =IF(COUNTIF($E$2:E5,E5)=1,ROW()-1,ROWS(Clean_Data[OrderID])+1) -> 901
A6: G0005 | B6: 46266 | C6: 7 | D6: C225 | E6: Returning | F6: North | G6: Beverages | H6: Juice | I6: 3 | J6: 115 | K6: 0.15 | L6: Delivered | M6: 32 | N6: 9 | O6: 4 | P6: =Clean_Data[[#This Row],[Quantity]]*Clean_Data[[#This Row],[UnitPrice]] -> 345 | Q6: =ROUND(Clean_Data[[#This Row],[GrossSales]]*Clean_Data[[#This Row],[DiscountPct]],2) -> 51.75 | R6: =IF(Clean_Data[[#This Row],[Status]]="Delivered",ROUND(Clean_Data[[#This Row],[GrossSales]]-Clean_Data[[#This Row],[DiscountAmount]],2),0) -> 293.25 | S6: =IF(Clean_Data[[#This Row],[OrderHour]]<6,"Night",IF(Clean_Data[[#This Row],[OrderHour]]<12,"Morning",IF(Clean_Data[[#This Row],[OrderHour]]<18,"Afternoon","Evening"))) -> Morning | T6: =TEXT(Clean_Data[[#This Row],[OrderDate]],"[$-409]ddd") -> Tue | U6: =WEEKDAY(Clean_Data[[#This Row],[OrderDate]],2) -> 2 | V6: =INT(Clean_Data[[#This Row],[OrderHour]]/6)+1 -> 2 | W6: =IF(Clean_Data[[#This Row],[Status]]="Delivered",1,0) -> 1 | X6: =IF(Clean_Data[[#This Row],[Status]]="Delivered",IF(Clean_Data[[#This Row],[DeliveryMinutes]]<=Dashboard!$X$5,1,0),0) -> 0 | Y6: =IF(AND(Clean_Data[[#This Row],[OrderDate]]>=Dashboard!$B$5,Clean_Data[[#This Row],[OrderDate]]<=Dashboard!$F$5,OR(Dashboard!$J$5="All",Clean_Data[[#This Row],[Zone]]=Dashboard!$J$5),OR(Dashboard!$P$5="All",Clean_Data[[#This Row],[Category]]=Dashboard!$P$5)),1,0) -> 1 | Z6: =IF(AND(Clean_Data[[#This Row],[Include]]=1,Clean_Data[[#This Row],[DeliveredFlag]]=1),1,0) -> 1 | AA6: =IF(COUNTIF($D$2:D6,D6)=1,ROW()-1,ROWS(Clean_Data[OrderID])+1) -> 5 | AB6: =IF(COUNTIF($F$2:F6,F6)=1,ROW()-1,ROWS(Clean_Data[OrderID])+1) -> 5 | AC6: =IF(COUNTIF($G$2:G6,G6)=1,ROW()-1,ROWS(Clean_Data[OrderID])+1) -> 5 | AD6: =IF(COUNTIF($H$2:H6,H6)=1,ROW()-1,ROWS(Clean_Data[OrderID])+1) -> 5 | AE6: =IF(COUNTIF($V$2:V6,V6)=1,V6,ROWS(Clean_Data[OrderID])+1) -> 2 | AF6: =IF(COUNTIF($U$2:U6,U6)=1,U6,ROWS(Clean_Data[OrderID])+1) -> 901 | AG6: =IF(COUNTIF($E$2:E6,E6)=1,ROW()-1,ROWS(Clean_Data[OrderID])+1) -> 901
A7: G0006 | B7: 46266 | C7: 9 | D7: C117 | E7: Returning | F7: North | G7: Beverages | H7: Tea | I7: 1 | J7: 145 | K7: 0 | L7: Delivered | M7: 21 | N7: 9 | O7: 4 | P7: =Clean_Data[[#This Row],[Quantity]]*Clean_Data[[#This Row],[UnitPrice]] -> 145 | Q7: =ROUND(Clean_Data[[#This Row],[GrossSales]]*Clean_Data[[#This Row],[DiscountPct]],2) -> 0 | R7: =IF(Clean_Data[[#This Row],[Status]]="Delivered",ROUND(Clean_Data[[#This Row],[GrossSales]]-Clean_Data[[#This Row],[DiscountAmount]],2),0) -> 145 | S7: =IF(Clean_Data[[#This Row],[OrderHour]]<6,"Night",IF(Clean_Data[[#This Row],[OrderHour]]<12,"Morning",IF(Clean_Data[[#This Row],[OrderHour]]<18,"Afternoon","Evening"))) -> Morning | T7: =TEXT(Clean_Data[[#This Row],[OrderDate]],"[$-409]ddd") -> Tue | U7: =WEEKDAY(Clean_Data[[#This Row],[OrderDate]],2) -> 2 | V7: =INT(Clean_Data[[#This Row],[OrderHour]]/6)+1 -> 2 | W7: =IF(Clean_Data[[#This Row],[Status]]="Delivered",1,0) -> 1 | X7: =IF(Clean_Data[[#This Row],[Status]]="Delivered",IF(Clean_Data[[#This Row],[DeliveryMinutes]]<=Dashboard!$X$5,1,0),0) -> 1 | Y7: =IF(AND(Clean_Data[[#This Row],[OrderDate]]>=Dashboard!$B$5,Clean_Data[[#This Row],[OrderDate]]<=Dashboard!$F$5,OR(Dashboard!$J$5="All",Clean_Data[[#This Row],[Zone]]=Dashboard!$J$5),OR(Dashboard!$P$5="All",Clean_Data[[#This Row],[Category]]=Dashboard!$P$5)),1,0) -> 1 | Z7: =IF(AND(Clean_Data[[#This Row],[Include]]=1,Clean_Data[[#This Row],[DeliveredFlag]]=1),1,0) -> 1 | AA7: =IF(COUNTIF($D$2:D7,D7)=1,ROW()-1,ROWS(Clean_Data[OrderID])+1) -> 6 | AB7: =IF(COUNTIF($F$2:F7,F7)=1,ROW()-1,ROWS(Clean_Data[OrderID])+1) -> 901 | AC7: =IF(COUNTIF($G$2:G7,G7)=1,ROW()-1,ROWS(Clean_Data[OrderID])+1) -> 901 | AD7: =IF(COUNTIF($H$2:H7,H7)=1,ROW()-1,ROWS(Clean_Data[OrderID])+1) -> 6 | AE7: =IF(COUNTIF($V$2:V7,V7)=1,V7,ROWS(Clean_Data[OrderID])+1) -> 901 | AF7: =IF(COUNTIF($U$2:U7,U7)=1,U7,ROWS(Clean_Data[OrderID])+1) -> 901 | AG7: =IF(COUNTIF($E$2:E7,E7)=1,ROW()-1,ROWS(Clean_Data[OrderID])+1) -> 901
A8: G0007 | B8: 46266 | C8: 18 | D8: C077 | E8: New | F8: West | G8: Bakery | H8: Bread | I8: 4 | J8: 45 | K8: 0.1 | L8: Delivered | M8: 28 | N8: 9 | O8: 4 | P8: =Clean_Data[[#This Row],[Quantity]]*Clean_Data[[#This Row],[UnitPrice]] -> 180 | Q8: =ROUND(Clean_Data[[#This Row],[GrossSales]]*Clean_Data[[#This Row],[DiscountPct]],2) -> 18 | R8: =IF(Clean_Data[[#This Row],[Status]]="Delivered",ROUND(Clean_Data[[#This Row],[GrossSales]]-Clean_Data[[#This Row],[DiscountAmount]],2),0) -> 162 | S8: =IF(Clean_Data[[#This Row],[OrderHour]]<6,"Night",IF(Clean_Data[[#This Row],[OrderHour]]<12,"Morning",IF(Clean_Data[[#This Row],[OrderHour]]<18,"Afternoon","Evening"))) -> Evening | T8: =TEXT(Clean_Data[[#This Row],[OrderDate]],"[$-409]ddd") -> Tue | U8: =WEEKDAY(Clean_Data[[#This Row],[OrderDate]],2) -> 2 | V8: =INT(Clean_Data[[#This Row],[OrderHour]]/6)+1 -> 4 | W8: =IF(Clean_Data[[#This Row],[Status]]="Delivered",1,0) -> 1 | X8: =IF(Clean_Data[[#This Row],[Status]]="Delivered",IF(Clean_Data[[#This Row],[DeliveryMinutes]]<=Dashboard!$X$5,1,0),0) -> 1 | Y8: =IF(AND(Clean_Data[[#This Row],[OrderDate]]>=Dashboard!$B$5,Clean_Data[[#This Row],[OrderDate]]<=Dashboard!$F$5,OR(Dashboard!$J$5="All",Clean_Data[[#This Row],[Zone]]=Dashboard!$J$5),OR(Dashboard!$P$5="All",Clean_Data[[#This Row],[Category]]=Dashboard!$P$5)),1,0) -> 1 | Z8: =IF(AND(Clean_Data[[#This Row],[Include]]=1,Clean_Data[[#This Row],[DeliveredFlag]]=1),1,0) -> 1 | AA8: =IF(COUNTIF($D$2:D8,D8)=1,ROW()-1,ROWS(Clean_Data[OrderID])+1) -> 7 | AB8: =IF(COUNTIF($F$2:F8,F8)=1,ROW()-1,ROWS(Clean_Data[OrderID])+1) -> 901 | AC8: =IF(COUNTIF($G$2:G8,G8)=1,ROW()-1,ROWS(Clean_Data[OrderID])+1) -> 901 | AD8: =IF(COUNTIF($H$2:H8,H8)=1,ROW()-1,ROWS(Clean_Data[OrderID])+1) -> 7 | AE8: =IF(COUNTIF($V$2:V8,V8)=1,V8,ROWS(Clean_Data[OrderID])+1) -> 901 | AF8: =IF(COUNTIF($U$2:U8,U8)=1,U8,ROWS(Clean_Data[OrderID])+1) -> 901 | AG8: =IF(COUNTIF($E$2:E8,E8)=1,ROW()-1,ROWS(Clean_Data[OrderID])+1) -> 7
A9: G0008 | B9: 46266 | C9: 21 | D9: C124 | E9: Returning | F9: South | G9: Produce | H9: Tomatoes | I9: 5 | J9: 45 | K9: 0 | L9: Delivered | M9: 24 | N9: 12 | O9: 4 | P9: =Clean_Data[[#This Row],[Quantity]]*Clean_Data[[#This Row],[UnitPrice]] -> 225 | Q9: =ROUND(Clean_Data[[#This Row],[GrossSales]]*Clean_Data[[#This Row],[DiscountPct]],2) -> 0 | R9: =IF(Clean_Data[[#This Row],[Status]]="Delivered",ROUND(Clean_Data[[#This Row],[GrossSales]]-Clean_Data[[#This Row],[DiscountAmount]],2),0) -> 225 | S9: =IF(Clean_Data[[#This Row],[OrderHour]]<6,"Night",IF(Clean_Data[[#This Row],[OrderHour]]<12,"Morning",IF(Clean_Data[[#This Row],[OrderHour]]<18,"Afternoon","Evening"))) -> Evening | T9: =TEXT(Clean_Data[[#This Row],[OrderDate]],"[$-409]ddd") -> Tue | U9: =WEEKDAY(Clean_Data[[#This Row],[OrderDate]],2) -> 2 | V9: =INT(Clean_Data[[#This Row],[OrderHour]]/6)+1 -> 4 | W9: =IF(Clean_Data[[#This Row],[Status]]="Delivered",1,0) -> 1 | X9: =IF(Clean_Data[[#This Row],[Status]]="Delivered",IF(Clean_Data[[#This Row],[DeliveryMinutes]]<=Dashboard!$X$5,1,0),0) -> 1 | Y9: =IF(AND(Clean_Data[[#This Row],[OrderDate]]>=Dashboard!$B$5,Clean_Data[[#This Row],[OrderDate]]<=Dashboard!$F$5,OR(Dashboard!$J$5="All",Clean_Data[[#This Row],[Zone]]=Dashboard!$J$5),OR(Dashboard!$P$5="All",Clean_Data[[#This Row],[Category]]=Dashboard!$P$5)),1,0) -> 1 | Z9: =IF(AND(Clean_Data[[#This Row],[Include]]=1,Clean_Data[[#This Row],[DeliveredFlag]]=1),1,0) -> 1 | AA9: =IF(COUNTIF($D$2:D9,D9)=1,ROW()-1,ROWS(Clean_Data[OrderID])+1) -> 8 | AB9: =IF(COUNTIF($F$2:F9,F9)=1,ROW()-1,ROWS(Clean_Data[OrderID])+1) -> 8 | AC9: =IF(COUNTIF($G$2:G9,G9)=1,ROW()-1,ROWS(Clean_Data[OrderID])+1) -> 8 | AD9: =IF(COUNTIF($H$2:H9,H9)=1,ROW()-1,ROWS(Clean_Data[OrderID])+1) -> 8 | AE9: =IF(COUNTIF($V$2:V9,V9)=1,V9,ROWS(Clean_Data[OrderID])+1) -> 901 | AF9: =IF(COUNTIF($U$2:U9,U9)=1,U9,ROWS(Clean_Data[OrderID])+1) -> 901 | AG9: =IF(COUNTIF($E$2:E9,E9)=1,ROW()-1,ROWS(Clean_Data[OrderID])+1) -> 901
A10: G0009 | B10: 46266 | C10: 19 | D10: C145 | E10: Returning | F10: Central | G10: Household | H10: Dish soap | I10: 1 | J10: 120 | K10: 0 | L10: Delivered | M10: 17 | N10: 15 | O10: 4 | P10: =Clean_Data[[#This Row],[Quantity]]*Clean_Data[[#This Row],[UnitPrice]] -> 120 | Q10: =ROUND(Clean_Data[[#This Row],[GrossSales]]*Clean_Data[[#This Row],[DiscountPct]],2) -> 0 | R10: =IF(Clean_Data[[#This Row],[Status]]="Delivered",ROUND(Clean_Data[[#This Row],[GrossSales]]-Clean_Data[[#This Row],[DiscountAmount]],2),0) -> 120 | S10: =IF(Clean_Data[[#This Row],[OrderHour]]<6,"Night",IF(Clean_Data[[#This Row],[OrderHour]]<12,"Morning",IF(Clean_Data[[#This Row],[OrderHour]]<18,"Afternoon","Evening"))) -> Evening | T10: =TEXT(Clean_Data[[#This Row],[OrderDate]],"[$-409]ddd") -> Tue | U10: =WEEKDAY(Clean_Data[[#This Row],[OrderDate]],2) -> 2 | V10: =INT(Clean_Data[[#This Row],[OrderHour]]/6)+1 -> 4 | W10: =IF(Clean_Data[[#This Row],[Status]]="Delivered",1,0) -> 1 | X10: =IF(Clean_Data[[#This Row],[Status]]="Delivered",IF(Clean_Data[[#This Row],[DeliveryMinutes]]<=Dashboard!$X$5,1,0),0) -> 1 | Y10: =IF(AND(Clean_Data[[#This Row],[OrderDate]]>=Dashboard!$B$5,Clean_Data[[#This Row],[OrderDate]]<=Dashboard!$F$5,OR(Dashboard!$J$5="All",Clean_Data[[#This Row],[Zone]]=Dashboard!$J$5),OR(Dashboard!$P$5="All",Clean_Data[[#This Row],[Category]]=Dashboard!$P$5)),1,0) -> 1 | Z10: =IF(AND(Clean_Data[[#This Row],[Include]]=1,Clean_Data[[#This Row],[DeliveredFlag]]=1),1,0) -> 1 | AA10: =IF(COUNTIF($D$2:D10,D10)=1,ROW()-1,ROWS(Clean_Data[OrderID])+1) -> 9 | AB10: =IF(COUNTIF($F$2:F10,F10)=1,ROW()-1,ROWS(Clean_Data[OrderID])+1) -> 901 | AC10: =IF(COUNTIF($G$2:G10,G10)=1,ROW()-1,ROWS(Clean_Data[OrderID])+1) -> 901 | AD10: =IF(COUNTIF($H$2:H10,H10)=1,ROW()-1,ROWS(Clean_Data[OrderID])+1) -> 901 | AE10: =IF(COUNTIF($V$2:V10,V10)=1,V10,ROWS(Clean_Data[OrderID])+1) -> 901 | AF10: =IF(COUNTIF($U$2:U10,U10)=1,U10,ROWS(Clean_Data[OrderID])+1) -> 901 | AG10: =IF(COUNTIF($E$2:E10,E10)=1,ROW()-1,ROWS(Clean_Data[OrderID])+1) -> 901
A11: G0010 | B11: 46266 | C11: 22 | D11: C249 | E11: Returning | F11: South | G11: Bakery | H11: Bread | I11: 4 | J11: 45 | K11: 0 | L11: Delivered | M11: 16 | N11: 12 | O11: 5 | P11: =Clean_Data[[#This Row],[Quantity]]*Clean_Data[[#This Row],[UnitPrice]] -> 180 | Q11: =ROUND(Clean_Data[[#This Row],[GrossSales]]*Clean_Data[[#This Row],[DiscountPct]],2) -> 0 | R11: =IF(Clean_Data[[#This Row],[Status]]="Delivered",ROUND(Clean_Data[[#This Row],[GrossSales]]-Clean_Data[[#This Row],[DiscountAmount]],2),0) -> 180 | S11: =IF(Clean_Data[[#This Row],[OrderHour]]<6,"Night",IF(Clean_Data[[#This Row],[OrderHour]]<12,"Morning",IF(Clean_Data[[#This Row],[OrderHour]]<18,"Afternoon","Evening"))) -> Evening | T11: =TEXT(Clean_Data[[#This Row],[OrderDate]],"[$-409]ddd") -> Tue | U11: =WEEKDAY(Clean_Data[[#This Row],[OrderDate]],2) -> 2 | V11: =INT(Clean_Data[[#This Row],[OrderHour]]/6)+1 -> 4 | W11: =IF(Clean_Data[[#This Row],[Status]]="Delivered",1,0) -> 1 | X11: =IF(Clean_Data[[#This Row],[Status]]="Delivered",IF(Clean_Data[[#This Row],[DeliveryMinutes]]<=Dashboard!$X$5,1,0),0) -> 1 | Y11: =IF(AND(Clean_Data[[#This Row],[OrderDate]]>=Dashboard!$B$5,Clean_Data[[#This Row],[OrderDate]]<=Dashboard!$F$5,OR(Dashboard!$J$5="All",Clean_Data[[#This Row],[Zone]]=Dashboard!$J$5),OR(Dashboard!$P$5="All",Clean_Data[[#This Row],[Category]]=Dashboard!$P$5)),1,0) -> 1 | Z11: =IF(AND(Clean_Data[[#This Row],[Include]]=1,Clean_Data[[#This Row],[DeliveredFlag]]=1),1,0) -> 1 | AA11: =IF(COUNTIF($D$2:D11,D11)=1,ROW()-1,ROWS(Clean_Data[OrderID])+1) -> 10 | AB11: =IF(COUNTIF($F$2:F11,F11)=1,ROW()-1,ROWS(Clean_Data[OrderID])+1) -> 901 | AC11: =IF(COUNTIF($G$2:G11,G11)=1,ROW()-1,ROWS(Clean_Data[OrderID])+1) -> 901 | AD11: =IF(COUNTIF($H$2:H11,H11)=1,ROW()-1,ROWS(Clean_Data[OrderID])+1) -> 901 | AE11: =IF(COUNTIF($V$2:V11,V11)=1,V11,ROWS(Clean_Data[OrderID])+1) -> 901 | AF11: =IF(COUNTIF($U$2:U11,U11)=1,U11,ROWS(Clean_Data[OrderID])+1) -> 901 | AG11: =IF(COUNTIF($E$2:E11,E11)=1,ROW()-1,ROWS(Clean_Data[OrderID])+1) -> 901
A12: G0011 | B12: 46266 | C12: 20 | D12: C233 | E12: Returning | F12: West | G12: Household | H12: Tissues | I12: 3 | J12: 85 | K12: 0 | L12: Delivered | M12: 34 | N12: 8 | O12: 5 | P12: =Clean_Data[[#This Row],[Quantity]]*Clean_Data[[#This Row],[UnitPrice]] -> 255 | Q12: =ROUND(Clean_Data[[#This Row],[GrossSales]]*Clean_Data[[#This Row],[DiscountPct]],2) -> 0 | R12: =IF(Clean_Data[[#This Row],[Status]]="Delivered",ROUND(Clean_Data[[#This Row],[GrossSales]]-Clean_Data[[#This Row],[DiscountAmount]],2),0) -> 255 | S12: =IF(Clean_Data[[#This Row],[OrderHour]]<6,"Night",IF(Clean_Data[[#This Row],[OrderHour]]<12,"Morning",IF(Clean_Data[[#This Row],[OrderHour]]<18,"Afternoon","Evening"))) -> Evening | T12: =TEXT(Clean_Data[[#This Row],[OrderDate]],"[$-409]ddd") -> Tue | U12: =WEEKDAY(Clean_Data[[#This Row],[OrderDate]],2) -> 2 | V12: =INT(Clean_Data[[#This Row],[OrderHour]]/6)+1 -> 4 | W12: =IF(Clean_Data[[#This Row],[Status]]="Delivered",1,0) -> 1 | X12: =IF(Clean_Data[[#This Row],[Status]]="Delivered",IF(Clean_Data[[#This Row],[DeliveryMinutes]]<=Dashboard!$X$5,1,0),0) -> 0 | Y12: =IF(AND(Clean_Data[[#This Row],[OrderDate]]>=Dashboard!$B$5,Clean_Data[[#This Row],[OrderDate]]<=Dashboard!$F$5,OR(Dashboard!$J$5="All",Clean_Data[[#This Row],[Zone]]=Dashboard!$J$5),OR(Dashboard!$P$5="All",Clean_Data[[#This Row],[Category]]=Dashboard!$P$5)),1,0) -> 1 | Z12: =IF(AND(Clean_Data[[#This Row],[Include]]=1,Clean_Data[[#This Row],[DeliveredFlag]]=1),1,0) -> 1 | AA12: =IF(COUNTIF($D$2:D12,D12)=1,ROW()-1,ROWS(Clean_Data[OrderID])+1) -> 11 | AB12: =IF(COUNTIF($F$2:F12,F12)=1,ROW()-1,ROWS(Clean_Data[OrderID])+1) -> 901 | AC12: =IF(COUNTIF($G$2:G12,G12)=1,ROW()-1,ROWS(Clean_Data[OrderID])+1) -> 901 | AD12: =IF(COUNTIF($H$2:H12,H12)=1,ROW()-1,ROWS(Clean_Data[OrderID])+1) -> 11 | AE12: =IF(COUNTIF($V$2:V12,V12)=1,V12,ROWS(Clean_Data[OrderID])+1) -> 901 | AF12: =IF(COUNTIF($U$2:U12,U12)=1,U12,ROWS(Clean_Data[OrderID])+1) -> 901 | AG12: =IF(COUNTIF($E$2:E12,E12)=1,ROW()-1,ROWS(Clean_Data[OrderID])+1) -> 901
A13: G0012 | B13: 46266 | C13: 23 | D13: C134 | E13: Returning | F13: North | G13: Beverages | H13: Juice | I13: 2 | J13: 115 | K13: 0.15 | L13: Delivered | M13: 22 | N13: 6 | O13: 4 | P13: =Clean_Data[[#This Row],[Quantity]]*Clean_Data[[#This Row],[UnitPrice]] -> 230 | Q13: =ROUND(Clean_Data[[#This Row],[GrossSales]]*Clean_Data[[#This Row],[DiscountPct]],2) -> 34.5 | R13: =IF(Clean_Data[[#This Row],[Status]]="Delivered",ROUND(Clean_Data[[#This Row],[GrossSales]]-Clean_Data[[#This Row],[DiscountAmount]],2),0) -> 195.5 | S13: =IF(Clean_Data[[#This Row],[OrderHour]]<6,"Night",IF(Clean_Data[[#This Row],[OrderHour]]<12,"Morning",IF(Clean_Data[[#This Row],[OrderHour]]<18,"Afternoon","Evening"))) -> Evening | T13: =TEXT(Clean_Data[[#This Row],[OrderDate]],"[$-409]ddd") -> Tue | U13: =WEEKDAY(Clean_Data[[#This Row],[OrderDate]],2) -> 2 | V13: =INT(Clean_Data[[#This Row],[OrderHour]]/6)+1 -> 4 | W13: =IF(Clean_Data[[#This Row],[Status]]="Delivered",1,0) -> 1 | X13: =IF(Clean_Data[[#This Row],[Status]]="Delivered",IF(Clean_Data[[#This Row],[DeliveryMinutes]]<=Dashboard!$X$5,1,0),0) -> 1 | Y13: =IF(AND(Clean_Data[[#This Row],[OrderDate]]>=Dashboard!$B$5,Clean_Data[[#This Row],[OrderDate]]<=Dashboard!$F$5,OR(Dashboard!$J$5="All",Clean_Data[[#This Row],[Zone]]=Dashboard!$J$5),OR(Dashboard!$P$5="All",Clean_Data[[#This Row],[Category]]=Dashboard!$P$5)),1,0) -> 1 | Z13: =IF(AND(Clean_Data[[#This Row],[Include]]=1,Clean_Data[[#This Row],[DeliveredFlag]]=1),1,0) -> 1 | AA13: =IF(COUNTIF($D$2:D13,D13)=1,ROW()-1,ROWS(Clean_Data[OrderID])+1) -> 12 | AB13: =IF(COUNTIF($F$2:F13,F13)=1,ROW()-1,ROWS(Clean_Data[OrderID])+1) -> 901 | AC13: =IF(COUNTIF($G$2:G13,G13)=1,ROW()-1,ROWS(Clean_Data[OrderID])+1) -> 901 | AD13: =IF(COUNTIF($H$2:H13,H13)=1,ROW()-1,ROWS(Clean_Data[OrderID])+1) -> 901 | AE13: =IF(COUNTIF($V$2:V13,V13)=1,V13,ROWS(Clean_Data[OrderID])+1) -> 901 | AF13: =IF(COUNTIF($U$2:U13,U13)=1,U13,ROWS(Clean_Data[OrderID])+1) -> 901 | AG13: =IF(COUNTIF($E$2:E13,E13)=1,ROW()-1,ROWS(Clean_Data[OrderID])+1) -> 901
A14: G0013 | B14: 46266 | C14: 7 | D14: C257 | E14: Returning | F14: North | G14: Snacks | H14: Chips | I14: 1 | J14: 40 | K14: 0.1 | L14: Cancelled | P14: =Clean_Data[[#This Row],[Quantity]]*Clean_Data[[#This Row],[UnitPrice]] -> 40 | Q14: =ROUND(Clean_Data[[#This Row],[GrossSales]]*Clean_Data[[#This Row],[DiscountPct]],2) -> 4 | R14: =IF(Clean_Data[[#This Row],[Status]]="Delivered",ROUND(Clean_Data[[#This Row],[GrossSales]]-Clean_Data[[#This Row],[DiscountAmount]],2),0) -> 0 | S14: =IF(Clean_Data[[#This Row],[OrderHour]]<6,"Night",IF(Clean_Data[[#This Row],[OrderHour]]<12,"Morning",IF(Clean_Data[[#This Row],[OrderHour]]<18,"Afternoon","Evening"))) -> Morning | T14: =TEXT(Clean_Data[[#This Row],[OrderDate]],"[$-409]ddd") -> Tue | U14: =WEEKDAY(Clean_Data[[#This Row],[OrderDate]],2) -> 2 | V14: =INT(Clean_Data[[#This Row],[OrderHour]]/6)+1 -> 2 | W14: =IF(Clean_Data[[#This Row],[Status]]="Delivered",1,0) -> 0 | X14: =IF(Clean_Data[[#This Row],[Status]]="Delivered",IF(Clean_Data[[#This Row],[DeliveryMinutes]]<=Dashboard!$X$5,1,0),0) -> 0 | Y14: =IF(AND(Clean_Data[[#This Row],[OrderDate]]>=Dashboard!$B$5,Clean_Data[[#This Row],[OrderDate]]<=Dashboard!$F$5,OR(Dashboard!$J$5="All",Clean_Data[[#This Row],[Zone]]=Dashboard!$J$5),OR(Dashboard!$P$5="All",Clean_Data[[#This Row],[Category]]=Dashboard!$P$5)),1,0) -> 1 | Z14: =IF(AND(Clean_Data[[#This Row],[Include]]=1,Clean_Data[[#This Row],[DeliveredFlag]]=1),1,0) -> 0 | AA14: =IF(COUNTIF($D$2:D14,D14)=1,ROW()-1,ROWS(Clean_Data[OrderID])+1) -> 13 | AB14: =IF(COUNTIF($F$2:F14,F14)=1,ROW()-1,ROWS(Clean_Data[OrderID])+1) -> 901 | AC14: =IF(COUNTIF($G$2:G14,G14)=1,ROW()-1,ROWS(Clean_Data[OrderID])+1) -> 13 | AD14: =IF(COUNTIF($H$2:H14,H14)=1,ROW()-1,ROWS(Clean_Data[OrderID])+1) -> 13 | AE14: =IF(COUNTIF($V$2:V14,V14)=1,V14,ROWS(Clean_Data[OrderID])+1) -> 901 | AF14: =IF(COUNTIF($U$2:U14,U14)=1,U14,ROWS(Clean_Data[OrderID])+1) -> 901 | AG14: =IF(COUNTIF($E$2:E14,E14)=1,ROW()-1,ROWS(Clean_Data[OrderID])+1) -> 901
A15: G0014 | B15: 46266 | C15: 6 | D15: C296 | E15: Returning | F15: East | G15: Produce | H15: Tomatoes | I15: 2 | J15: 45 | K15: 0.15 | L15: Delivered | M15: 31 | N15: 5 | O15: 4 | P15: =Clean_Data[[#This Row],[Quantity]]*Clean_Data[[#This Row],[UnitPrice]] -> 90 | Q15: =ROUND(Clean_Data[[#This Row],[GrossSales]]*Clean_Data[[#This Row],[DiscountPct]],2) -> 13.5 | R15: =IF(Clean_Data[[#This Row],[Status]]="Delivered",ROUND(Clean_Data[[#This Row],[GrossSales]]-Clean_Data[[#This Row],[DiscountAmount]],2),0) -> 76.5 | S15: =IF(Clean_Data[[#This Row],[OrderHour]]<6,"Night",IF(Clean_Data[[#This Row],[OrderHour]]<12,"Morning",IF(Clean_Data[[#This Row],[OrderHour]]<18,"Afternoon","Evening"))) -> Morning | T15: =TEXT(Clean_Data[[#This Row],[OrderDate]],"[$-409]ddd") -> Tue | U15: =WEEKDAY(Clean_Data[[#This Row],[OrderDate]],2) -> 2 | V15: =INT(Clean_Data[[#This Row],[OrderHour]]/6)+1 -> 2 | W15: =IF(Clean_Data[[#This Row],[Status]]="Delivered",1,0) -> 1 | X15: =IF(Clean_Data[[#This Row],[Status]]="Delivered",IF(Clean_Data[[#This Row],[DeliveryMinutes]]<=Dashboard!$X$5,1,0),0) -> 0 | Y15: =IF(AND(Clean_Data[[#This Row],[OrderDate]]>=Dashboard!$B$5,Clean_Data[[#This Row],[OrderDate]]<=Dashboard!$F$5,OR(Dashboard!$J$5="All",Clean_Data[[#This Row],[Zone]]=Dashboard!$J$5),OR(Dashboard!$P$5="All",Clean_Data[[#This Row],[Category]]=Dashboard!$P$5)),1,0) -> 1 | Z15: =IF(AND(Clean_Data[[#This Row],[Include]]=1,Clean_Data[[#This Row],[DeliveredFlag]]=1),1,0) -> 1 | AA15: =IF(COUNTIF($D$2:D15,D15)=1,ROW()-1,ROWS(Clean_Data[OrderID])+1) -> 14 | AB15: =IF(COUNTIF($F$2:F15,F15)=1,ROW()-1,ROWS(Clean_Data[OrderID])+1) -> 14 | AC15: =IF(COUNTIF($G$2:G15,G15)=1,ROW()-1,ROWS(Clean_Data[OrderID])+1) -> 901 | AD15: =IF(COUNTIF($H$2:H15,H15)=1,ROW()-1,ROWS(Clean_Data[OrderID])+1) -> 901 | AE15: =IF(COUNTIF($V$2:V15,V15)=1,V15,ROWS(Clean_Data[OrderID])+1) -> 901 | AF15: =IF(COUNTIF($U$2:U15,U15)=1,U15,ROWS(Clean_Data[OrderID])+1) -> 901 | AG15: =IF(COUNTIF($E$2:E15,E15)=1,ROW()-1,ROWS(Clean_Data[OrderID])+1) -> 901
A16: G0015 | B16: 46266 | C16: 12 | D16: C184 | E16: Returning | F16: South | G16: Beverages | H16: Juice | I16: 1 | J16: 115 | K16: 0 | L16: Delivered | M16: 27 | N16: 13 | O16: 3 | P16: =Clean_Data[[#This Row],[Quantity]]*Clean_Data[[#This Row],[UnitPrice]] -> 115 | Q16: =ROUND(Clean_Data[[#This Row],[GrossSales]]*Clean_Data[[#This Row],[DiscountPct]],2) -> 0 | R16: =IF(Clean_Data[[#This Row],[Status]]="Delivered",ROUND(Clean_Data[[#This Row],[GrossSales]]-Clean_Data[[#This Row],[DiscountAmount]],2),0) -> 115 | S16: =IF(Clean_Data[[#This Row],[OrderHour]]<6,"Night",IF(Clean_Data[[#This Row],[OrderHour]]<12,"Morning",IF(Clean_Data[[#This Row],[OrderHour]]<18,"Afternoon","Evening"))) -> Afternoon | T16: =TEXT(Clean_Data[[#This Row],[OrderDate]],"[$-409]ddd") -> Tue | U16: =WEEKDAY(Clean_Data[[#This Row],[OrderDate]],2) -> 2 | V16: =INT(Clean_Data[[#This Row],[OrderHour]]/6)+1 -> 3 | W16: =IF(Clean_Data[[#This Row],[Status]]="Delivered",1,0) -> 1 | X16: =IF(Clean_Data[[#This Row],[Status]]="Delivered",IF(Clean_Data[[#This Row],[DeliveryMinutes]]<=Dashboard!$X$5,1,0),0) -> 1 | Y16: =IF(AND(Clean_Data[[#This Row],[OrderDate]]>=Dashboard!$B$5,Clean_Data[[#This Row],[OrderDate]]<=Dashboard!$F$5,OR(Dashboard!$J$5="All",Clean_Data[[#This Row],[Zone]]=Dashboard!$J$5),OR(Dashboard!$P$5="All",Clean_Data[[#This Row],[Category]]=Dashboard!$P$5)),1,0) -> 1 | Z16: =IF(AND(Clean_Data[[#This Row],[Include]]=1,Clean_Data[[#This Row],[DeliveredFlag]]=1),1,0) -> 1 | AA16: =IF(COUNTIF($D$2:D16,D16)=1,ROW()-1,ROWS(Clean_Data[OrderID])+1) -> 15 | AB16: =IF(COUNTIF($F$2:F16,F16)=1,ROW()-1,ROWS(Clean_Data[OrderID])+1) -> 901 | AC16: =IF(COUNTIF($G$2:G16,G16)=1,ROW()-1,ROWS(Clean_Data[OrderID])+1) -> 901 | AD16: =IF(COUNTIF($H$2:H16,H16)=1,ROW()-1,ROWS(Clean_Data[OrderID])+1) -> 901 | AE16: =IF(COUNTIF($V$2:V16,V16)=1,V16,ROWS(Clean_Data[OrderID])+1) -> 901 | AF16: =IF(COUNTIF($U$2:U16,U16)=1,U16,ROWS(Clean_Data[OrderID])+1) -> 901 | AG16: =IF(COUNTIF($E$2:E16,E16)=1,ROW()-1,ROWS(Clean_Data[OrderID])+1) -> 901
A17: G0016 | B17: 46266 | C17: 11 | D17: C229 | E17: Returning | F17: West | G17: Household | H17: Tissues | I17: 6 | J17: 85 | K17: 0.15 | L17: Delivered | M17: 35 | N17: 9 | O17: 4 | P17: =Clean_Data[[#This Row],[Quantity]]*Clean_Data[[#This Row],[UnitPrice]] -> 510 | Q17: =ROUND(Clean_Data[[#This Row],[GrossSales]]*Clean_Data[[#This Row],[DiscountPct]],2) -> 76.5 | R17: =IF(Clean_Data[[#This Row],[Status]]="Delivered",ROUND(Clean_Data[[#This Row],[GrossSales]]-Clean_Data[[#This Row],[DiscountAmount]],2),0) -> 433.5 | S17: =IF(Clean_Data[[#This Row],[OrderHour]]<6,"Night",IF(Clean_Data[[#This Row],[OrderHour]]<12,"Morning",IF(Clean_Data[[#This Row],[OrderHour]]<18,"Afternoon","Evening"))) -> Morning | T17: =TEXT(Clean_Data[[#This Row],[OrderDate]],"[$-409]ddd") -> Tue | U17: =WEEKDAY(Clean_Data[[#This Row],[OrderDate]],2) -> 2 | V17: =INT(Clean_Data[[#This Row],[OrderHour]]/6)+1 -> 2 | W17: =IF(Clean_Data[[#This Row],[Status]]="Delivered",1,0) -> 1 | X17: =IF(Clean_Data[[#This Row],[Status]]="Delivered",IF(Clean_Data[[#This Row],[DeliveryMinutes]]<=Dashboard!$X$5,1,0),0) -> 0 | Y17: =IF(AND(Clean_Data[[#This Row],[OrderDate]]>=Dashboard!$B$5,Clean_Data[[#This Row],[OrderDate]]<=Dashboard!$F$5,OR(Dashboard!$J$5="All",Clean_Data[[#This Row],[Zone]]=Dashboard!$J$5),OR(Dashboard!$P$5="All",Clean_Data[[#This Row],[Category]]=Dashboard!$P$5)),1,0) -> 1 | Z17: =IF(AND(Clean_Data[[#This Row],[Include]]=1,Clean_Data[[#This Row],[DeliveredFlag]]=1),1,0) -> 1 | AA17: =IF(COUNTIF($D$2:D17,D17)=1,ROW()-1,ROWS(Clean_Data[OrderID])+1) -> 16 | AB17: =IF(COUNTIF($F$2:F17,F17)=1,ROW()-1,ROWS(Clean_Data[OrderID])+1) -> 901 | AC17: =IF(COUNTIF($G$2:G17,G17)=1,ROW()-1,ROWS(Clean_Data[OrderID])+1) -> 901 | AD17: =IF(COUNTIF($H$2:H17,H17)=1,ROW()-1,ROWS(Clean_Data[OrderID])+1) -> 901 | AE17: =IF(COUNTIF($V$2:V17,V17)=1,V17,ROWS(Clean_Data[OrderID])+1) -> 901 | AF17: =IF(COUNTIF($U$2:U17,U17)=1,U17,ROWS(Clean_Data[OrderID])+1) -> 901 | AG17: =IF(COUNTIF($E$2:E17,E17)=1,ROW()-1,ROWS(Clean_Data[OrderID])+1) -> 901
A18: G0017 | B18: 46266 | C18: 17 | D18: C004 | E18: New | F18: South | G18: Bakery | H18: Cookies | I18: 6 | J18: 110 | K18: 0 | L18: Delivered | M18: 25 | N18: 6 | O18: 5 | P18: =Clean_Data[[#This Row],[Quantity]]*Clean_Data[[#This Row],[UnitPrice]] -> 660 | Q18: =ROUND(Clean_Data[[#This Row],[GrossSales]]*Clean_Data[[#This Row],[DiscountPct]],2) -> 0 | R18: =IF(Clean_Data[[#This Row],[Status]]="Delivered",ROUND(Clean_Data[[#This Row],[GrossSales]]-Clean_Data[[#This Row],[DiscountAmount]],2),0) -> 660 | S18: =IF(Clean_Data[[#This Row],[OrderHour]]<6,"Night",IF(Clean_Data[[#This Row],[OrderHour]]<12,"Morning",IF(Clean_Data[[#This Row],[OrderHour]]<18,"Afternoon","Evening"))) -> Afternoon | T18: =TEXT(Clean_Data[[#This Row],[OrderDate]],"[$-409]ddd") -> Tue | U18: =WEEKDAY(Clean_Data[[#This Row],[OrderDate]],2) -> 2 | V18: =INT(Clean_Data[[#This Row],[OrderHour]]/6)+1 -> 3 | W18: =IF(Clean_Data[[#This Row],[Status]]="Delivered",1,0) -> 1 | X18: =IF(Clean_Data[[#This Row],[Status]]="Delivered",IF(Clean_Data[[#This Row],[DeliveryMinutes]]<=Dashboard!$X$5,1,0),0) -> 1 | Y18: =IF(AND(Clean_Data[[#This Row],[OrderDate]]>=Dashboard!$B$5,Clean_Data[[#This Row],[OrderDate]]<=Dashboard!$F$5,OR(Dashboard!$J$5="All",Clean_Data[[#This Row],[Zone]]=Dashboard!$J$5),OR(Dashboard!$P$5="All",Clean_Data[[#This Row],[Category]]=Dashboard!$P$5)),1,0) -> 1 | Z18: =IF(AND(Clean_Data[[#This Row],[Include]]=1,Clean_Data[[#This Row],[DeliveredFlag]]=1),1,0) -> 1 | AA18: =IF(COUNTIF($D$2:D18,D18)=1,ROW()-1,ROWS(Clean_Data[OrderID])+1) -> 17 | AB18: =IF(COUNTIF($F$2:F18,F18)=1,ROW()-1,ROWS(Clean_Data[OrderID])+1) -> 901 | AC18: =IF(COUNTIF($G$2:G18,G18)=1,ROW()-1,ROWS(Clean_Data[OrderID])+1) -> 901 | AD18: =IF(COUNTIF($H$2:H18,H18)=1,ROW()-1,ROWS(Clean_Data[OrderID])+1) -> 17 | AE18: =IF(COUNTIF($V$2:V18,V18)=1,V18,ROWS(Clean_Data[OrderID])+1) -> 901 | AF18: =IF(COUNTIF($U$2:U18,U18)=1,U18,ROWS(Clean_Data[OrderID])+1) -> 901 | AG18: =IF(COUNTIF($E$2:E18,E18)=1,ROW()-1,ROWS(Clean_Data[OrderID])+1) -> 901
